[2023-04-29T06:27:42.931+0000] {taskinstance.py:1087} INFO - Dependencies all met for <TaskInstance: Extract.extract manual__2023-04-29T06:27:39.165872+00:00 [queued]>
[2023-04-29T06:27:42.952+0000] {taskinstance.py:1087} INFO - Dependencies all met for <TaskInstance: Extract.extract manual__2023-04-29T06:27:39.165872+00:00 [queued]>
[2023-04-29T06:27:42.953+0000] {taskinstance.py:1283} INFO - 
--------------------------------------------------------------------------------
[2023-04-29T06:27:42.955+0000] {taskinstance.py:1284} INFO - Starting attempt 1 of 2
[2023-04-29T06:27:42.992+0000] {taskinstance.py:1285} INFO - 
--------------------------------------------------------------------------------
[2023-04-29T06:27:43.103+0000] {taskinstance.py:1304} INFO - Executing <Task(PythonOperator): extract> on 2023-04-29 06:27:39.165872+00:00
[2023-04-29T06:27:43.115+0000] {standard_task_runner.py:55} INFO - Started process 68 to run task
[2023-04-29T06:27:43.122+0000] {standard_task_runner.py:82} INFO - Running: ['***', 'tasks', 'run', 'Extract', 'extract', 'manual__2023-04-29T06:27:39.165872+00:00', '--job-id', '233', '--raw', '--subdir', 'DAGS_FOLDER/Dag.py', '--cfg-path', '/tmp/tmpwq1jalvt']
[2023-04-29T06:27:43.126+0000] {standard_task_runner.py:83} INFO - Job 233: Subtask extract
[2023-04-29T06:27:43.333+0000] {task_command.py:389} INFO - Running <TaskInstance: Extract.extract manual__2023-04-29T06:27:39.165872+00:00 [running]> on host 46ac91bb69b9
[2023-04-29T06:27:43.547+0000] {taskinstance.py:1511} INFO - Exporting the following env vars:
AIRFLOW_CTX_DAG_OWNER=Lina Arroyo
AIRFLOW_CTX_DAG_ID=Extract
AIRFLOW_CTX_TASK_ID=extract
AIRFLOW_CTX_EXECUTION_DATE=2023-04-29T06:27:39.165872+00:00
AIRFLOW_CTX_TRY_NUMBER=1
AIRFLOW_CTX_DAG_RUN_ID=manual__2023-04-29T06:27:39.165872+00:00
[2023-04-29T06:27:43.551+0000] {taskinstance.py:1772} ERROR - Task failed with exception
Traceback (most recent call last):
  File "/home/airflow/.local/lib/python3.10/site-packages/airflow/operators/python.py", line 175, in execute
    return_value = self.execute_callable()
  File "/home/airflow/.local/lib/python3.10/site-packages/airflow/operators/python.py", line 192, in execute_callable
    return self.python_callable(*self.op_args, **self.op_kwargs)
  File "/opt/airflow/dags/Dag.py", line 17, in extract
    data = pd.read_csv(path)
  File "/home/airflow/.local/lib/python3.10/site-packages/pandas/util/_decorators.py", line 211, in wrapper
    return func(*args, **kwargs)
  File "/home/airflow/.local/lib/python3.10/site-packages/pandas/util/_decorators.py", line 331, in wrapper
    return func(*args, **kwargs)
  File "/home/airflow/.local/lib/python3.10/site-packages/pandas/io/parsers/readers.py", line 950, in read_csv
    return _read(filepath_or_buffer, kwds)
  File "/home/airflow/.local/lib/python3.10/site-packages/pandas/io/parsers/readers.py", line 605, in _read
    parser = TextFileReader(filepath_or_buffer, **kwds)
  File "/home/airflow/.local/lib/python3.10/site-packages/pandas/io/parsers/readers.py", line 1442, in __init__
    self._engine = self._make_engine(f, self.engine)
  File "/home/airflow/.local/lib/python3.10/site-packages/pandas/io/parsers/readers.py", line 1735, in _make_engine
    self.handles = get_handle(
  File "/home/airflow/.local/lib/python3.10/site-packages/pandas/io/common.py", line 856, in get_handle
    handle = open(
FileNotFoundError: [Errno 2] No such file or directory: 'Data\\Traffic_Flow_Map_Volumes.csv'
[2023-04-29T06:27:43.568+0000] {taskinstance.py:1322} INFO - Marking task as UP_FOR_RETRY. dag_id=Extract, task_id=extract, execution_date=20230429T062739, start_date=20230429T062742, end_date=20230429T062743
[2023-04-29T06:27:43.754+0000] {standard_task_runner.py:100} ERROR - Failed to execute job 233 for task extract ([Errno 2] No such file or directory: 'Data\\Traffic_Flow_Map_Volumes.csv'; 68)
[2023-04-29T06:27:43.783+0000] {local_task_job.py:159} INFO - Task exited with return code 1
[2023-04-29T06:27:43.888+0000] {taskinstance.py:2582} INFO - 0 downstream tasks scheduled from follow-on schedule check
